<?xml version="1.0" ?>
<!-- =================================================================================== -->
<!-- |    This document was autogenerated by xacro from model.urdf.xacro               | -->
<!-- |    EDITING THIS FILE BY HAND IS NOT RECOMMENDED                                 | -->
<!-- =================================================================================== -->
<robot name="bot1">
  <!-- Specify some standard inertial calculations https://en.wikipedia.org/wiki/List_of_moments_of_inertia -->
  <!-- These make use of xacro's mathematical functionality -->
  <material name="white">
    <color rgba="1 1 1 1"/>
  </material>
  <material name="orange">
    <color rgba="1 0.3 0.1 1"/>
  </material>
  <material name="blue">
    <color rgba="0.2 0.2 1 1"/>
  </material>
  <material name="black">
    <color rgba="0 0 0 1"/>
  </material>
  <material name="red">
    <color rgba="1 0 0 1"/>
  </material>
  <!-- MACRO FOR THE WHEELS -->
  <!-- BASE LINK -->
  <link name="base_link"/>
  <link name="base_footprint"/>
  <!-- BASE_FOOTPRINT LINK -->
  <joint name="base_footprint_joint" type="fixed">
    <child link="base_footprint"/>
    <parent link="base_link"/>
    <origin rpy="0 0 0" xyz="0 0 0"/>
  </joint>
  <!-- CHASSIS LINK -->
  <joint name="chassis_joint" type="fixed">
    <parent link="base_link"/>
    <child link="chassis"/>
    <origin rpy="0 0 0" xyz="0 0 0.08"/>
  </joint>
  <link name="chassis">
    <visual>
      <origin xyz="0 0 0.1"/>
      <geometry>
        <box size="0.5 0.3 0.2"/>
      </geometry>
      <material name="orange"/>
    </visual>
    <collision>
      <origin xyz="0 0 0.1"/>
      <geometry>
        <box size="0.5 0.3 0.2"/>
      </geometry>
    </collision>
    <inertial>
      <origin rpy="0 0 0" xyz="0 0 0.1"/>
      <mass value="0.5"/>
      <inertia ixx="0.005416666666666667" ixy="0.0" ixz="0.0" iyy="0.012083333333333335" iyz="0.0" izz="0.014166666666666664"/>
    </inertial>
  </link>
  <gazebo reference="chassis">
    <material>Gazebo/Orange</material>
  </gazebo>
  <joint name="chassis_rear_right_wheel" type="continuous">
    <parent link="chassis"/>
    <child link="rear_right_wheel"/>
    <origin rpy="0 1.5707963267948966 1.5707963267948966" xyz="-0.15 0.1925 0"/>
    <axis xyz="0 1 0"/>
  </joint>
  <link name="rear_right_wheel">
    <visual>
      <geometry>
        <cylinder length="0.085" radius="0.08"/>
      </geometry>
      <origin rpy="0 0 3.141592653589793" xyz="0 0 0"/>
      <material name="white"/>
    </visual>
    <collision>
      <geometry>
        <cylinder length="0.085" radius="0.08"/>
      </geometry>
      <origin rpy="0 0 3.141592653589793" xyz="0 0 0"/>
    </collision>
    <inertial>
      <origin rpy="0 0 3.141592653589793" xyz="0 0 0"/>
      <mass value="0.05"/>
      <inertia ixx="0.00011010416666666666" ixy="0.0" ixz="0.0" iyy="0.00011010416666666666" iyz="0.0" izz="0.00016"/>
    </inertial>
  </link>
  <gazebo reference="rear_right_wheel">
    <material>Gazebo/Blue</material>
  </gazebo>
  <joint name="chassis_rear_left_wheel" type="continuous">
    <parent link="chassis"/>
    <child link="rear_left_wheel"/>
    <origin rpy="0 1.5707963267948966 1.5707963267948966" xyz="-0.15 -0.1925 0"/>
    <axis xyz="0 1 0"/>
  </joint>
  <link name="rear_left_wheel">
    <visual>
      <geometry>
        <cylinder length="0.085" radius="0.08"/>
      </geometry>
      <origin rpy="0 0 0.0" xyz="0 0 0"/>
      <material name="white"/>
    </visual>
    <collision>
      <geometry>
        <cylinder length="0.085" radius="0.08"/>
      </geometry>
      <origin rpy="0 0 0.0" xyz="0 0 0"/>
    </collision>
    <inertial>
      <origin rpy="0 0 0.0" xyz="0 0 0"/>
      <mass value="0.05"/>
      <inertia ixx="0.00011010416666666666" ixy="0.0" ixz="0.0" iyy="0.00011010416666666666" iyz="0.0" izz="0.00016"/>
    </inertial>
  </link>
  <gazebo reference="rear_left_wheel">
    <material>Gazebo/Blue</material>
  </gazebo>
  <!-- Yaw link -->
  <link name="caster_yaw_link">
    <inertial>
      <mass value="0.01"/>
      <inertia ixx="1e-5" ixy="0" ixz="0" iyy="1e-5" iyz="0" izz="1e-5"/>
    </inertial>
  </link>
  <!-- Swivel -->
  <joint name="caster_yaw_joint" type="continuous">
    <parent link="chassis"/>
    <child link="caster_yaw_link"/>
    <origin rpy="0 0 0" xyz="0.15 0 0"/>
    <axis xyz="0 0 1"/>
  </joint>
  <!-- Caster wheel -->
  <link name="caster">
    <visual>
      <origin rpy="0 0 0" xyz="0 0 0"/>
      <geometry>
        <sphere radius="0.04"/>
      </geometry>
      <material name="white"/>
    </visual>
    <collision>
      <origin rpy="0 0 0" xyz="0 0 0"/>
      <geometry>
        <sphere radius="0.04"/>
      </geometry>
    </collision>
    <inertial>
      <origin xyz="0 0 0"/>
      <mass value="0.5"/>
      <inertia ixx="0.00032" ixy="0.0" ixz="0.0" iyy="0.00032" iyz="0.0" izz="0.00032"/>
    </inertial>
  </link>
  <!-- Roll -->
  <joint name="caster_wheel_joint" type="continuous">
    <parent link="caster_yaw_link"/>
    <child link="caster"/>
    <origin rpy="0 0 0" xyz="0 0 -0.04"/>
    <axis xyz="0 1 0"/>
  </joint>
  <gazebo reference="caster">
    <mu1>0.6</mu1>
    <mu2>0.6</mu2>
  </gazebo>
  <gazebo>
    <!-- Differential Drive Plugin -->
    <!--official documentation-->
    <!--https://gazebosim.org/api/sim/8/classgz_1_1sim_1_1systems_1_1DiffDrive.html-->
    <!--this Plugin will publish those topics-->
    <!--/model/bot1/odometry    publisher   gz.msgs.Odometry-->
    <!--/model/bot1/tf          publisher   gz.msgs.Pose_V      publish the transform from frame_id to child_frame_id-->
    <!--/model/bot1/cmd_vel     subscriber  gz.msgs.Twist    -->
    <!--/model/bot1/enable      subscriber  gz.msgs.Boolean-->
    <plugin filename="gz-sim-diff-drive-system" name="gz::sim::systems::DiffDrive">
      <left_joint>chassis_left_wheel</left_joint>
      <right_joint>chassis_right_wheel</right_joint>
      <wheel_separation>0.385</wheel_separation>
      <!-- track width -->
      <wheel_radius>0.08</wheel_radius>
      <!-- Control parameters -->
      <!--            <odom_publish_frequency>50</odom_publish_frequency>-->
      <!--            <max_linear_acceleration>1.0</max_linear_acceleration>-->
      <!--            <min_linear_acceleration>-1.0</min_linear_acceleration>-->
      <!--            <max_angular_acceleration>2.0</max_angular_acceleration>-->
      <!--            <min_angular_acceleration>-2.0</min_angular_acceleration>-->
      <!--            <max_linear_velocity>0.5</max_linear_velocity>-->
      <!--            <min_linear_velocity>-0.5</min_linear_velocity>-->
      <!--            <max_angular_velocity>1.0</max_angular_velocity>-->
      <!--            <min_angular_velocity>-1.0</min_angular_velocity>-->
      <!-- Topic configuration -->
      <!--            <topic>cmd_vel</topic>-->
      <!--            <odom_topic>odom</odom_topic>-->
      <!--            @todo tbd if neccessary-->
      <frame_id>odom</frame_id>
      <child_frame_id>base_footprint</child_frame_id>
    </plugin>
    <!-- Joint State Publisher -->
    <!--official documentation-->
    <!--https://gazebosim.org/api/sim/8/classgz_1_1sim_1_1systems_1_1JointStatePublisher.html-->
    <plugin filename="gz-sim-joint-state-publisher-system" name="gz::sim::systems::JointStatePublisher">
      <!--            <joint_name>left_wheel_joint</joint_name>-->
      <!--            <joint_name>right_wheel_joint</joint_name>-->
      <!--            <joint_name>caster_yaw_joint</joint_name>-->
      <!--            <joint_name>caster_wheel_joint</joint_name>-->
    </plugin>
    <!-- Pose Publisher (optional, for debugging) -->
    <!--        <plugin filename="gz-sim-pose-publisher-system"-->
    <!--                name="gz::sim::systems::PosePublisher">-->
    <!--            <publish_link_pose>true</publish_link_pose>-->
    <!--            <publish_collision_pose>false</publish_collision_pose>-->
    <!--            <publish_visual_pose>false</publish_visual_pose>-->
    <!--            <publish_nested_model_pose>false</publish_nested_model_pose>-->
    <!--            <use_pose_vector_msg>true</use_pose_vector_msg>-->
    <!--            <update_frequency>50</update_frequency>-->
    <!--        </plugin>-->
  </gazebo>
  <!--    <xacro:include filename="gazebo_sensors/lidar.xacro" />-->
  <!--    <xacro:include filename="gazebo_sensors/gps.xacro" />-->
  <!--    <xacro:include filename="gazebo_sensors/imu.xacro" />-->
  <!--    <xacro:include filename="gazebo_sensors/collision_sensor.xacro" />-->
  <!--    <xacro:include filename="gazebo_sensors/camera.xacro" />-->
  <!--    <xacro:include filename="gazebo_sensors/lidarAS.xacro" />-->
</robot>
