<?xml version="1.0" ?>
<!-- =================================================================================== -->
<!-- |    This document was autogenerated by xacro from model.urdf.xacro               | -->
<!-- |    EDITING THIS FILE BY HAND IS NOT RECOMMENDED                                 | -->
<!-- =================================================================================== -->
<robot name="bot1">
  <!-- Specify some standard inertial calculations https://en.wikipedia.org/wiki/List_of_moments_of_inertia -->
  <!-- These make use of xacro's mathematical functionality -->
  <material name="white">
    <color rgba="1 1 1 1"/>
  </material>
  <material name="orange">
    <color rgba="1 0.3 0.1 1"/>
  </material>
  <material name="blue">
    <color rgba="0.2 0.2 1 1"/>
  </material>
  <material name="black">
    <color rgba="0 0 0 1"/>
  </material>
  <material name="red">
    <color rgba="1 0 0 1"/>
  </material>
  <!-- MACRO FOR THE WHEELS -->
  <!-- BASE LINK -->
  <link name="base_link"/>
  <link name="base_footprint"/>
  <!-- BASE_FOOTPRINT LINK -->
  <joint name="base_footprint_joint" type="fixed">
    <parent link="base_footprint"/>
    <child link="base_link"/>
    <origin rpy="0 0 0" xyz="0 0 0"/>
  </joint>
  <!-- CHASSIS LINK -->
  <joint name="chassis_joint" type="fixed">
    <parent link="base_link"/>
    <child link="chassis"/>
    <origin rpy="0 0 0" xyz="0 0 0.08"/>
  </joint>
  <link name="chassis">
    <visual>
      <origin xyz="0 0 0.1"/>
      <geometry>
        <box size="0.5 0.3 0.2"/>
      </geometry>
      <material name="orange"/>
    </visual>
    <collision>
      <origin xyz="0 0 0.1"/>
      <geometry>
        <box size="0.5 0.3 0.2"/>
      </geometry>
    </collision>
    <inertial>
      <origin rpy="0 0 0" xyz="0 0 0.1"/>
      <mass value="0.5"/>
      <inertia ixx="0.005416666666666667" ixy="0.0" ixz="0.0" iyy="0.012083333333333335" iyz="0.0" izz="0.014166666666666664"/>
    </inertial>
  </link>
  <gazebo reference="chassis">
    <material>Gazebo/Orange</material>
  </gazebo>
  <joint name="chassis_rear_right_wheel" type="continuous">
    <parent link="chassis"/>
    <child link="rear_right_wheel"/>
    <origin rpy="0 1.5707963267948966 1.5707963267948966" xyz="-0.15 0.1925 0"/>
    <axis xyz="0 0 1"/>
  </joint>
  <link name="rear_right_wheel">
    <visual>
      <geometry>
        <cylinder length="0.085" radius="0.08"/>
      </geometry>
      <origin rpy="0 0 3.141592653589793" xyz="0 0 0"/>
      <material name="white"/>
    </visual>
    <collision>
      <geometry>
        <cylinder length="0.085" radius="0.08"/>
      </geometry>
      <origin rpy="0 0 3.141592653589793" xyz="0 0 0"/>
    </collision>
    <inertial>
      <origin rpy="0 0 3.141592653589793" xyz="0 0 0"/>
      <mass value="0.05"/>
      <inertia ixx="0.00011010416666666666" ixy="0.0" ixz="0.0" iyy="0.00011010416666666666" iyz="0.0" izz="0.00016"/>
    </inertial>
  </link>
  <gazebo reference="rear_right_wheel">
    <material>Gazebo/Blue</material>
  </gazebo>
  <joint name="chassis_rear_left_wheel" type="continuous">
    <parent link="chassis"/>
    <child link="rear_left_wheel"/>
    <origin rpy="0 1.5707963267948966 1.5707963267948966" xyz="-0.15 -0.1925 0"/>
    <axis xyz="0 0 1"/>
  </joint>
  <link name="rear_left_wheel">
    <visual>
      <geometry>
        <cylinder length="0.085" radius="0.08"/>
      </geometry>
      <origin rpy="0 0 0.0" xyz="0 0 0"/>
      <material name="white"/>
    </visual>
    <collision>
      <geometry>
        <cylinder length="0.085" radius="0.08"/>
      </geometry>
      <origin rpy="0 0 0.0" xyz="0 0 0"/>
    </collision>
    <inertial>
      <origin rpy="0 0 0.0" xyz="0 0 0"/>
      <mass value="0.05"/>
      <inertia ixx="0.00011010416666666666" ixy="0.0" ixz="0.0" iyy="0.00011010416666666666" iyz="0.0" izz="0.00016"/>
    </inertial>
  </link>
  <gazebo reference="rear_left_wheel">
    <material>Gazebo/Blue</material>
  </gazebo>
  <!-- Yaw link -->
  <link name="caster_yaw_link">
    <inertial>
      <mass value="0.01"/>
      <inertia ixx="1e-5" ixy="0" ixz="0" iyy="1e-5" iyz="0" izz="1e-5"/>
    </inertial>
  </link>
  <!-- Swivel -->
  <joint name="caster_yaw_joint" type="continuous">
    <parent link="chassis"/>
    <child link="caster_yaw_link"/>
    <origin rpy="0 0 0" xyz="0.15 0 0"/>
    <axis xyz="0 0 1"/>
  </joint>
  <!-- Caster wheel -->
  <link name="caster">
    <visual>
      <origin rpy="0 0 0" xyz="0 0 0"/>
      <geometry>
        <sphere radius="0.04"/>
      </geometry>
      <material name="white"/>
    </visual>
    <collision>
      <origin rpy="0 0 0" xyz="0 0 0"/>
      <geometry>
        <sphere radius="0.04"/>
      </geometry>
    </collision>
    <inertial>
      <origin xyz="0 0 0"/>
      <mass value="0.5"/>
      <inertia ixx="0.00032" ixy="0.0" ixz="0.0" iyy="0.00032" iyz="0.0" izz="0.00032"/>
    </inertial>
  </link>
  <!-- Roll -->
  <joint name="caster_wheel_joint" type="continuous">
    <parent link="caster_yaw_link"/>
    <child link="caster"/>
    <origin rpy="0 0 0" xyz="0 0 -0.04"/>
    <axis xyz="0 1 0"/>
  </joint>
  <gazebo reference="caster">
    <mu1>0.01</mu1>
    <mu2>0.01</mu2>
  </gazebo>
  <gazebo>
    <!-- Differential Drive Plugin -->
    <!--official documentation-->
    <!--https://gazebosim.org/api/sim/8/classgz_1_1sim_1_1systems_1_1DiffDrive.html-->
    <!--this Plugin will publish those topics-->
    <!--/model/bot1/odometry    publisher   gz.msgs.Odometry-->
    <!--/model/bot1/tf          publisher   gz.msgs.Pose_V      publish the transform from frame_id to child_frame_id-->
    <!--/model/bot1/cmd_vel     subscriber  gz.msgs.Twist    -->
    <!--/model/bot1/enable      subscriber  gz.msgs.Boolean-->
    <plugin filename="gz-sim-diff-drive-system" name="gz::sim::systems::DiffDrive">
      <left_joint>chassis_rear_left_wheel</left_joint>
      <right_joint>chassis_rear_right_wheel</right_joint>
      <wheel_separation>0.385</wheel_separation>
      <!-- track width -->
      <wheel_radius>0.08</wheel_radius>
      <!-- Control parameters -->
      <!--            <odom_publish_frequency>50</odom_publish_frequency>-->
      <!--            <max_linear_acceleration>1.0</max_linear_acceleration>-->
      <!--            <min_linear_acceleration>-1.0</min_linear_acceleration>-->
      <!--            <max_angular_acceleration>2.0</max_angular_acceleration>-->
      <!--            <min_angular_acceleration>-2.0</min_angular_acceleration>-->
      <!--            <max_linear_velocity>0.5</max_linear_velocity>-->
      <!--            <min_linear_velocity>-0.5</min_linear_velocity>-->
      <!--            <max_angular_velocity>1.0</max_angular_velocity>-->
      <!--            <min_angular_velocity>-1.0</min_angular_velocity>-->
      <!-- Topic configuration -->
      <!--            <topic>cmd_vel</topic>-->
      <!--            <odom_topic>odom</odom_topic>-->
      <!--            @todo tbd if neccessary-->
      <frame_id>odom</frame_id>
      <child_frame_id>base_footprint</child_frame_id>
    </plugin>
    <!-- Joint State Publisher -->
    <!--official documentation-->
    <!--https://gazebosim.org/api/sim/8/classgz_1_1sim_1_1systems_1_1JointStatePublisher.html-->
    <plugin filename="gz-sim-joint-state-publisher-system" name="gz::sim::systems::JointStatePublisher">
      <joint_name>chassis_rear_left_wheel</joint_name>
      <joint_name>chassis_rear_right_wheel</joint_name>
      <joint_name>caster_yaw_joint</joint_name>
      <joint_name>caster_wheel_joint</joint_name>
    </plugin>
    <!-- Pose Publisher (optional, for debugging) -->
    <plugin filename="gz-sim-pose-publisher-system" name="gz::sim::systems::PosePublisher">
      <publish_link_pose>true</publish_link_pose>
      <publish_collision_pose>false</publish_collision_pose>
      <publish_visual_pose>false</publish_visual_pose>
      <publish_nested_model_pose>false</publish_nested_model_pose>
      <use_pose_vector_msg>true</use_pose_vector_msg>
      <update_frequency>50</update_frequency>
    </plugin>
  </gazebo>
  <joint name="laser_joint" type="fixed">
    <parent link="chassis"/>
    <child link="laser"/>
    <origin rpy="0 0 0" xyz="0.18999999999999997 -0.10099999999999999 0.22"/>
  </joint>
  <link name="laser">
    <visual>
      <geometry>
        <cylinder length="0.04" radius="0.019"/>
      </geometry>
      <material name="red"/>
    </visual>
    <collision>
      <geometry>
        <cylinder length="0.04" radius="0.019"/>
      </geometry>
    </collision>
    <inertial>
      <origin rpy="0 0 0" xyz="0 0 0"/>
      <mass value="0.1"/>
      <inertia ixx="2.2358333333333332e-05" ixy="0.0" ixz="0.0" iyy="2.2358333333333332e-05" iyz="0.0" izz="1.805e-05"/>
    </inertial>
  </link>
  <gazebo reference="laser">
    <sensor name="LidarCircularSensor" type="gpu_lidar">
      <pose relative_to="laser_joint">0 0 0.013 0 0 0</pose>
      <topic>/scangz</topic>
      <update_rate>10</update_rate>
      <ray>
        <scan>
          <horizontal>
            <samples>640</samples>
            <resolution>1</resolution>
            <min_angle>-2.14159</min_angle>
            <max_angle>2.14159</max_angle>
          </horizontal>
          <vertical>
            <samples>1</samples>
            <resolution>0.01</resolution>
            <min_angle>0</min_angle>
            <max_angle>0</max_angle>
          </vertical>
        </scan>
        <range>
          <min>0.08</min>
          <max>20.0</max>
          <resolution>0.01</resolution>
        </range>
      </ray>
      <always_on>1</always_on>
      <visualize>true</visualize>
      <!-- <frame_id>lidar</frame_id> -->
    </sensor>
  </gazebo>
  <joint name="gps_joint" type="fixed">
    <parent link="chassis"/>
    <child link="gps"/>
    <origin rpy="0 0 0" xyz="-0.185 -0.09999999999999999 0.30000000000000004"/>
  </joint>
  <link name="gps">
    <visual>
      <geometry>
        <cylinder length="0.02" radius="0.01"/>
      </geometry>
      <material name="red"/>
    </visual>
    <collision>
      <geometry>
        <cylinder length="0.02" radius="0.01"/>
      </geometry>
    </collision>
    <inertial>
      <origin rpy="0 0 0" xyz="0 0 0"/>
      <mass value="0.1"/>
      <inertia ixx="5.833333333333333e-06" ixy="0.0" ixz="0.0" iyy="5.833333333333333e-06" iyz="0.0" izz="5e-06"/>
    </inertial>
  </link>
  <gazebo reference="gps">
    <sensor name="navsat" type="navsat">
      <pose relative_to="gps_joint">0 0 0.013 0 0 0</pose>
      <always_on>1</always_on>
      <update_rate>1</update_rate>
      <!--            <topic>/navsat</topic>-->
      <position_sensing>
        <horizontal>
          <noise bais_mean="0" bais_stddev="0.003 " dynamic_bias_correlation_time="7200" dynamic_bias_stdddev="10" mean="0" stddev="0.05" type="gaussian"/>
        </horizontal>
        <vertical>
          <noise bais_mean="0" bais_stddev="0.003 " dynamic_bias_correlation_time="7200" dynamic_bias_stdddev="10" mean="0" stddev="0.05" type="gaussian"/>
        </vertical>
      </position_sensing>
      <velocity_sensing>
        <horizontal>
          <noise bais_mean="0" bais_stddev="0.003 " dynamic_bias_correlation_time="7200" dynamic_bias_stdddev="10" mean="0" stddev="0.05" type="gaussian"/>
        </horizontal>
        <vertical>
          <noise bais_mean="0" bais_stddev="0.003 " dynamic_bias_correlation_time="7200" dynamic_bias_stdddev="10" mean="0" stddev="0.05" type="gaussian"/>
        </vertical>
      </velocity_sensing>
    </sensor>
  </gazebo>
  <joint name="imu_joint" type="fixed">
    <parent link="chassis"/>
    <child link="imu"/>
    <origin rpy="0 0 0" xyz="0.03499999999999999 0.0 0.21000000000000002"/>
  </joint>
  <link name="imu">
    <visual>
      <geometry>
        <box size="0.01 0.01 0.005"/>
      </geometry>
      <material name="red"/>
    </visual>
    <collision>
      <geometry>
        <box size="0.01 0.01 0.005"/>
      </geometry>
    </collision>
    <inertial>
      <origin rpy="0 0 0" xyz="0 0 0"/>
      <mass value="0.001"/>
      <inertia ixx="1.0416666666666667e-08" ixy="0.0" ixz="0.0" iyy="1.0416666666666667e-08" iyz="0.0" izz="1.6666666666666667e-08"/>
    </inertial>
  </link>
  <gazebo reference="imu">
    <!--Documentation-->
    <!--https://sdformat.org/spec/1.11/sensor/#sensor_imu-->
    <sensor name="imu_sensor" type="imu">
      <always_on>1</always_on>
      <update_rate>50</update_rate>
      <visualize>true</visualize>
      <enable_metrics>true</enable_metrics>
      <!--            <topic>/imu</topic>-->
      <angular_velocity>
        <x>
          <noise bais_mean="0" bais_stddev="0.003 " dynamic_bias_correlation_time="7200" dynamic_bias_stdddev="10" mean="0" stddev="0.05" type="gaussian"/>
        </x>
        <y>
          <noise bais_mean="0" bais_stddev="0.003 " dynamic_bias_correlation_time="7200" dynamic_bias_stdddev="10" mean="0" stddev="0.05" type="gaussian"/>
        </y>
        <z>
          <noise bais_mean="0" bais_stddev="0.003 " dynamic_bias_correlation_time="7200" dynamic_bias_stdddev="10" mean="0" stddev="0.05" type="gaussian"/>
        </z>
      </angular_velocity>
      <linear_accelaration>
        <x>
          <noise bais_mean="0" bais_stddev="0.0001 " dynamic_bias_correlation_time="7200" dynamic_bias_stdddev="0.0001" mean="0" stddev="0.00126" type="gaussian"/>
        </x>
        <y>
          <noise bais_mean="0" bais_stddev="0.0001 " dynamic_bias_correlation_time="7200" dynamic_bias_stdddev="0.0001" mean="0" stddev="0.00126" type="gaussian"/>
        </y>
        <z>
          <noise bais_mean="0" bais_stddev="0.0001 " dynamic_bias_correlation_time="7200" dynamic_bias_stdddev="0.0001" mean="0" stddev="0.00126" type="gaussian"/>
        </z>
      </linear_accelaration>
    </sensor>
  </gazebo>
  <!--    <xacro:include filename="gazebo_sensors/collision_sensor.xacro" />-->
  <!--    <xacro:include filename="gazebo_sensors/camera.xacro" />-->
  <!--    <xacro:include filename="gazebo_sensors/lidarAS.xacro" />-->
</robot>
